<?xml version="1.0" encoding="UTF-8"?>
<robot name="anymal_c">
  <joint name="LF_HAA" type="revolute">
    <origin xyz="0.2999 0.104 0." rpy="2.6179938 0. 0."/>
    <parent link="anymal"/>
    <child link="LF_HIP"/>
    <axis xyz="1. 0. 0."/>
    <limit lower="-0.72" upper="0.49" effort="80." velocity="20.000001"/>
  </joint>
  <joint name="LF_HFE" type="revolute">
    <origin xyz="0.0599 0.08381 0." rpy="-2.6179938 0. 1.5707964"/>
    <parent link="LF_HIP"/>
    <child link="LF_THIGH"/>
    <axis xyz="1. 0. 0."/>
    <limit lower="-9.424778" upper="9.424778" effort="80." velocity="20.000001"/>
  </joint>
  <joint name="LF_KFE" type="revolute">
    <origin xyz="0. 0.1003 -0.285" rpy="0. 0. -0.0000001"/>
    <parent link="LF_THIGH"/>
    <child link="LF_SHANK"/>
    <axis xyz="1. 0. 0."/>
    <limit lower="-9.424778" upper="9.424778" effort="80." velocity="20.000001"/>
  </joint>
  <joint name="LF_shank_fixed_LF_FOOT" type="fixed">
    <origin xyz="0.08795 0.01305 -0.33797" rpy="0. 0. -1.5707966"/>
    <parent link="LF_SHANK"/>
    <child link="LF_FOOT"/>
  </joint>
  <joint name="LH_HAA" type="revolute">
    <origin xyz="-0.2999 0.104 0." rpy="-2.6179938 0. 3.1415925"/>
    <parent link="anymal"/>
    <child link="LH_HIP"/>
    <axis xyz="1. 0. 0."/>
    <limit lower="-0.72" upper="0.49" effort="80." velocity="20.000001"/>
  </joint>
  <joint name="LH_HFE" type="revolute">
    <origin xyz="-0.0599 0.08381 0." rpy="0.5235988 0. 1.5707964"/>
    <parent link="LH_HIP"/>
    <child link="LH_THIGH"/>
    <axis xyz="1. 0. 0."/>
    <limit lower="-9.424778" upper="9.424778" effort="80." velocity="20.000001"/>
  </joint>
  <joint name="LH_KFE" type="revolute">
    <origin xyz="-0.0001968 0.1003 -0.2849999" rpy="0.0006905 0. -0.0000001"/>
    <parent link="LH_THIGH"/>
    <child link="LH_SHANK"/>
    <axis xyz="1. 0. 0."/>
    <limit lower="-9.424778" upper="9.424778" effort="80." velocity="20.000001"/>
  </joint>
  <joint name="LH_shank_fixed_LH_FOOT" type="fixed">
    <origin xyz="-0.08828 0.01305 -0.3378839" rpy="0. 0.0009765 -1.5707966"/>
    <parent link="LH_SHANK"/>
    <child link="LH_FOOT"/>
  </joint>
  <joint name="RF_HAA" type="revolute">
    <origin xyz="0.2999 -0.104 0." rpy="-2.6179938 0. 0."/>
    <parent link="anymal"/>
    <child link="RF_HIP"/>
    <axis xyz="1. 0. 0."/>
    <limit lower="-0.49" upper="0.72" effort="80." velocity="20.000001"/>
  </joint>
  <joint name="RF_HFE" type="revolute">
    <origin xyz="0.0599 -0.08381 0." rpy="2.6179938 0. -1.5707964"/>
    <parent link="RF_HIP"/>
    <child link="RF_THIGH"/>
    <axis xyz="1. 0. 0."/>
    <limit lower="-9.424778" upper="9.424778" effort="80." velocity="20.000001"/>
  </joint>
  <joint name="RF_KFE" type="revolute">
    <origin xyz="0. -0.1003 -0.285" rpy="3.1415925 0. -0.0000001"/>
    <parent link="RF_THIGH"/>
    <child link="RF_SHANK"/>
    <axis xyz="1. 0. 0."/>
    <limit lower="-9.424778" upper="9.424778" effort="80." velocity="20.000001"/>
  </joint>
  <joint name="RF_shank_fixed_RF_FOOT" type="fixed">
    <origin xyz="0.08795 -0.01305 -0.33797" rpy="3.1415925 0. 1.5707966"/>
    <parent link="RF_SHANK"/>
    <child link="RF_FOOT"/>
  </joint>
  <joint name="RH_HAA" type="revolute">
    <origin xyz="-0.2999 -0.104 0." rpy="2.6179938 0. 3.1415925"/>
    <parent link="anymal"/>
    <child link="RH_HIP"/>
    <axis xyz="1. 0. 0."/>
    <limit lower="-0.49" upper="0.72" effort="80." velocity="20.000001"/>
  </joint>
  <joint name="RH_HFE" type="revolute">
    <origin xyz="-0.0599 -0.08381 0." rpy="-0.5235988 0. -1.5707964"/>
    <parent link="RH_HIP"/>
    <child link="RH_THIGH"/>
    <axis xyz="1. 0. 0."/>
    <limit lower="-9.424778" upper="9.424778" effort="80." velocity="20.000001"/>
  </joint>
  <joint name="RH_KFE" type="revolute">
    <origin xyz="0.0001968 -0.1003 -0.2849999" rpy="3.142283 -0.0000001 1.5707962"/>
    <parent link="RH_THIGH"/>
    <child link="RH_SHANK"/>
    <axis xyz="1. 0. 0."/>
    <limit lower="-9.424778" upper="9.424778" effort="80." velocity="20.000001"/>
  </joint>
  <joint name="RH_shank_fixed_RH_FOOT" type="fixed">
    <origin xyz="-0.0876199 -0.01305 -0.3380557" rpy="3.1415925 -0.0009765 1.5707966"/>
    <parent link="RH_SHANK"/>
    <child link="RH_FOOT"/>
  </joint>
  <link name="LF_FOOT">
    <inertial>
      <origin xyz="0.00948 -0.00948 0.1468" rpy="0. 0. 0."/>
      <mass value="0.25"/>
      <inertia ixx="0.0031717" ixy="0." ixz="0." iyy="0.0031717" iyz="0." izz="0.0000832"/>
    </inertial>
  </link>
  <link name="LF_HIP">
    <inertial>
      <origin xyz="-0.063 0.00007 0.00046" rpy="0. 0. 0."/>
      <mass value="2.78"/>
      <inertia ixx="0.001053" ixy="0." ixz="0." iyy="0.0018055" iyz="0." izz="0.0017658"/>
    </inertial>
  </link>
  <link name="LF_SHANK">
    <inertial>
      <origin xyz="-0.063 0.00007 0.00046" rpy="0. 0. 0."/>
      <mass value="2.37742"/>
      <inertia ixx="0.001053" ixy="0." ixz="0." iyy="0.0018055" iyz="0." izz="0.0017658"/>
    </inertial>
  </link>
  <link name="LF_THIGH">
    <inertial>
      <origin xyz="-0.063 0.00007 0.00046" rpy="0. 0. 0."/>
      <mass value="3.07"/>
      <inertia ixx="0.001053" ixy="0." ixz="0." iyy="0.0018055" iyz="0." izz="0.0017658"/>
    </inertial>
  </link>
  <link name="LH_FOOT">
    <inertial>
      <origin xyz="-0.00948 -0.00948 0.1468" rpy="0. 0. 0."/>
      <mass value="0.25"/>
      <inertia ixx="0.0031717" ixy="0." ixz="0." iyy="0.0031717" iyz="0." izz="0.0000832"/>
    </inertial>
  </link>
  <link name="LH_HIP">
    <inertial>
      <origin xyz="-0.063 0.00007 0.00046" rpy="0. 0. 0."/>
      <mass value="2.78"/>
      <inertia ixx="0.001053" ixy="0." ixz="0." iyy="0.0018055" iyz="0." izz="0.0017658"/>
    </inertial>
  </link>
  <link name="LH_SHANK">
    <inertial>
      <origin xyz="-0.063 0.00007 0.00046" rpy="0. 0. 0."/>
      <mass value="2.37742"/>
      <inertia ixx="0.001053" ixy="0." ixz="0." iyy="0.0018055" iyz="0." izz="0.0017658"/>
    </inertial>
  </link>
  <link name="LH_THIGH">
    <inertial>
      <origin xyz="-0.063 0.00007 0.00046" rpy="0. 0. 0."/>
      <mass value="3.07"/>
      <inertia ixx="0.001053" ixy="0." ixz="0." iyy="0.0018055" iyz="0." izz="0.0017658"/>
    </inertial>
  </link>
  <link name="RF_FOOT">
    <inertial>
      <origin xyz="0.00948 0.00948 0.1468" rpy="0. 0. 0."/>
      <mass value="0.25"/>
      <inertia ixx="0.0031717" ixy="0." ixz="0." iyy="0.0031717" iyz="0." izz="0.0000832"/>
    </inertial>
  </link>
  <link name="RF_HIP">
    <inertial>
      <origin xyz="-0.063 0.00007 0.00046" rpy="0. 0. 0."/>
      <mass value="2.78"/>
      <inertia ixx="0.001053" ixy="0." ixz="0." iyy="0.0018055" iyz="0." izz="0.0017658"/>
    </inertial>
  </link>
  <link name="RF_SHANK">
    <inertial>
      <origin xyz="-0.063 0.00007 0.00046" rpy="0. 0. 0."/>
      <mass value="2.37742"/>
      <inertia ixx="0.001053" ixy="0." ixz="0." iyy="0.0018055" iyz="0." izz="0.0017658"/>
    </inertial>
  </link>
  <link name="RF_THIGH">
    <inertial>
      <origin xyz="-0.063 0.00007 0.00046" rpy="0. 0. 0."/>
      <mass value="3.07"/>
      <inertia ixx="0.001053" ixy="0." ixz="0." iyy="0.0018055" iyz="0." izz="0.0017658"/>
    </inertial>
  </link>
  <link name="RH_FOOT">
    <inertial>
      <origin xyz="-0.00948 0.00948 0.1468" rpy="0. 0. 0."/>
      <mass value="0.25"/>
      <inertia ixx="0.0031717" ixy="0." ixz="0." iyy="0.0031717" iyz="0." izz="0.0000832"/>
    </inertial>
  </link>
  <link name="RH_HIP">
    <inertial>
      <origin xyz="-0.063 0.00007 0.00046" rpy="0. 0. 0."/>
      <mass value="2.78"/>
      <inertia ixx="0.001053" ixy="0." ixz="0." iyy="0.0018055" iyz="0." izz="0.0017658"/>
    </inertial>
  </link>
  <link name="RH_SHANK">
    <inertial>
      <origin xyz="-0.063 0.00007 0.00046" rpy="0. 0. 0."/>
      <mass value="2.37742"/>
      <inertia ixx="0.001053" ixy="0." ixz="0." iyy="0.0018055" iyz="0." izz="0.0017658"/>
    </inertial>
  </link>
  <link name="RH_THIGH">
    <inertial>
      <origin xyz="-0.063 0.00007 0.00046" rpy="0. 0. 0."/>
      <mass value="3.07"/>
      <inertia ixx="0.001053" ixy="0." ixz="0." iyy="0.0018055" iyz="0." izz="0.0017658"/>
    </inertial>
  </link>
  <link name="anymal"/>
</robot>
