<?xml version="1.0" encoding="UTF-8"?>
<robot name="anymal_b">
  <joint name="LF_ADAPTER_TO_FOOT" type="fixed">
    <origin xyz="-0.02 -0.1 -0.32125" rpy="0. 0. -1.5707964"/>
    <parent link="LF_SHANK"/>
    <child link="LF_FOOT"/>
  </joint>
  <joint name="LF_HAA" type="revolute">
    <origin xyz="0.277 0.116 0. " rpy="0. 0. 0."/>
    <parent link="anymal"/>
    <child link="LF_HIP"/>
    <axis xyz="1. 0. 0."/>
    <limit lower="-9.4199992" upper="9.4199992" effort="80." velocity="15.0000002"/>
  </joint>
  <joint name="LF_HFE" type="revolute">
    <origin xyz="0.0635 0.041 0. " rpy="0. 0. 1.5707964"/>
    <parent link="LF_HIP"/>
    <child link="LF_THIGH"/>
    <axis xyz="1. 0. 0."/>
    <limit lower="-9.4199992" upper="9.4199992" effort="80." velocity="20.000001"/>
  </joint>
  <joint name="LF_KFE" type="revolute">
    <origin xyz="0.109 0. -0.25 " rpy="0. 0. 0."/>
    <parent link="LF_THIGH"/>
    <child link="LF_SHANK"/>
    <axis xyz="1. 0. 0."/>
    <limit lower="-9.4199992" upper="9.4199992" effort="80." velocity="20.000001"/>
  </joint>
  <joint name="LH_ADAPTER_TO_FOOT" type="fixed">
    <origin xyz="-0.02 0.1 -0.32125" rpy="0. 0. -1.5707964"/>
    <parent link="LH_SHANK"/>
    <child link="LH_FOOT"/>
  </joint>
  <joint name="LH_HAA" type="revolute">
    <origin xyz="-0.277 0.116 0. " rpy="0. 0. 0."/>
    <parent link="anymal"/>
    <child link="LH_HIP"/>
    <axis xyz="1. 0. 0."/>
    <limit lower="-9.4199992" upper="9.4199992" effort="80." velocity="15.0000002"/>
  </joint>
  <joint name="LH_HFE" type="revolute">
    <origin xyz="-0.0635 0.041 0. " rpy="0. 0. 1.5707964"/>
    <parent link="LH_HIP"/>
    <child link="LH_THIGH"/>
    <axis xyz="1. 0. 0."/>
    <limit lower="-9.4199992" upper="9.4199992" effort="80." velocity="20.000001"/>
  </joint>
  <joint name="LH_KFE" type="revolute">
    <origin xyz="0.109 -0. -0.25 " rpy="0. 0. 0."/>
    <parent link="LH_THIGH"/>
    <child link="LH_SHANK"/>
    <axis xyz="1. 0. 0."/>
    <limit lower="-9.4199992" upper="9.4199992" effort="80." velocity="20.000001"/>
  </joint>
  <joint name="RF_ADAPTER_TO_FOOT" type="fixed">
    <origin xyz="0.02 -0.1 -0.32125" rpy="0. 0. -1.5707964"/>
    <parent link="RF_SHANK"/>
    <child link="RF_FOOT"/>
  </joint>
  <joint name="RF_HAA" type="revolute">
    <origin xyz="0.277 -0.116 0. " rpy="0. 0. 0."/>
    <parent link="anymal"/>
    <child link="RF_HIP"/>
    <axis xyz="1. 0. 0."/>
    <limit lower="-9.4199992" upper="9.4199992" effort="80." velocity="20.000001"/>
  </joint>
  <joint name="RF_HFE" type="revolute">
    <origin xyz="0.0635 -0.041 0. " rpy="0. 0. 1.5707964"/>
    <parent link="RF_HIP"/>
    <child link="RF_THIGH"/>
    <axis xyz="1. 0. 0."/>
    <limit lower="-9.4199992" upper="9.4199992" effort="80." velocity="20.000001"/>
  </joint>
  <joint name="RF_KFE" type="revolute">
    <origin xyz="-0.109 0. -0.25 " rpy="0. 0. 0."/>
    <parent link="RF_THIGH"/>
    <child link="RF_SHANK"/>
    <axis xyz="1. 0. 0."/>
    <limit lower="-9.4199992" upper="9.4199992" effort="80." velocity="20.000001"/>
  </joint>
  <joint name="RH_ADAPTER_TO_FOOT" type="fixed">
    <origin xyz="0.02 0.1 -0.32125" rpy="0. 0. -1.5707964"/>
    <parent link="RH_SHANK"/>
    <child link="RH_FOOT"/>
  </joint>
  <joint name="RH_HAA" type="revolute">
    <origin xyz="-0.277 -0.116 0. " rpy="0. 0. 0."/>
    <parent link="anymal"/>
    <child link="RH_HIP"/>
    <axis xyz="1. 0. 0."/>
    <limit lower="-9.4199992" upper="9.4199992" effort="80." velocity="15.0000002"/>
  </joint>
  <joint name="RH_HFE" type="revolute">
    <origin xyz="-0.0635 -0.041 0. " rpy="0. 0. 1.5707964"/>
    <parent link="RH_HIP"/>
    <child link="RH_THIGH"/>
    <axis xyz="1. 0. 0."/>
    <limit lower="-9.4199992" upper="9.4199992" effort="80." velocity="20.000001"/>
  </joint>
  <joint name="RH_KFE" type="revolute">
    <origin xyz="-0.109 -0. -0.25 " rpy="0. 0. 0."/>
    <parent link="RH_THIGH"/>
    <child link="RH_SHANK"/>
    <axis xyz="1. 0. 0."/>
    <limit lower="-9.4199992" upper="9.4199992" effort="80." velocity="20.000001"/>
  </joint>
  <link name="LF_FOOT">
    <inertial>
      <origin xyz="0. 0. 0.02325" rpy="0. 0. 0."/>
      <mass value="0.05"/>
      <inertia ixx="0.001" ixy="-0.0000003" ixz="0.0000068" iyy="0.001" iyz="-0.0000068" izz="0.0000083"/>
    </inertial>
  </link>
  <link name="LF_HIP">
    <inertial>
      <origin xyz="0.0645163 -0.0037871 -0.0001522" rpy="0. 0. 0."/>
      <mass value="1.4246206"/>
      <inertia ixx="0.0024302" ixy="-0.0000153" ixz="-0.0000218" iyy="0.0023026" iyz="0.0000265" izz="0.0019807"/>
    </inertial>
  </link>
  <link name="LF_SHANK">
    <inertial>
      <origin xyz="0.0587332 -0.0108244 -0.0980642" rpy="0. 0. 0."/>
      <mass value="0.3473751"/>
      <inertia ixx="0.0068581" ixy="0.0000322" ixz="0.0014287" iyy="0.0077043" iyz="-0.0003162" izz="0.0010194"/>
    </inertial>
  </link>
  <link name="LF_THIGH">
    <inertial>
      <origin xyz="-0.003898 0.0542266 -0.2145834" rpy="0. 0. 0."/>
      <mass value="1.6349765"/>
      <inertia ixx="0.0120368" ixy="0.0000676" ixz="0.0002878" iyy="0.0120644" iyz="-0.0014061" izz="0.0024942"/>
    </inertial>
  </link>
  <link name="LH_FOOT">
    <inertial>
      <origin xyz="0. 0. 0.02325" rpy="0. 0. 0."/>
      <mass value="0.05"/>
      <inertia ixx="0.001" ixy="-0.0000003" ixz="0.0000068" iyy="0.001" iyz="-0.0000068" izz="0.0000083"/>
    </inertial>
  </link>
  <link name="LH_HIP">
    <inertial>
      <origin xyz="-0.0645163 -0.0037871 -0.0001522" rpy="0. 0. 0."/>
      <mass value="1.4246206"/>
      <inertia ixx="0.0024302" ixy="0.0000153" ixz="0.0000218" iyy="0.0023026" iyz="0.0000265" izz="0.0019807"/>
    </inertial>
  </link>
  <link name="LH_SHANK">
    <inertial>
      <origin xyz="-0.0587332 -0.0108244 -0.0980642" rpy="0. 0. 0."/>
      <mass value="0.3473751"/>
      <inertia ixx="0.0068581" ixy="-0.0000322" ixz="-0.0014287" iyy="0.0077043" iyz="-0.0003162" izz="0.0010194"/>
    </inertial>
  </link>
  <link name="LH_THIGH">
    <inertial>
      <origin xyz="0.003898 0.0542266 -0.2145834" rpy="0. 0. 0."/>
      <mass value="1.6349765"/>
      <inertia ixx="0.0120368" ixy="-0.0000676" ixz="-0.0002878" iyy="0.0120644" iyz="-0.0014061" izz="0.0024942"/>
    </inertial>
  </link>
  <link name="RF_FOOT">
    <inertial>
      <origin xyz="0. 0. 0.02325" rpy="0. 0. 0."/>
      <mass value="0.05"/>
      <inertia ixx="0.001" ixy="-0.0000003" ixz="0.0000068" iyy="0.001" iyz="-0.0000068" izz="0.0000083"/>
    </inertial>
  </link>
  <link name="RF_HIP">
    <inertial>
      <origin xyz="0.0645163 0.0037871 -0.0001522" rpy="0. 0. 0."/>
      <mass value="1.4246206"/>
      <inertia ixx="0.0024302" ixy="0.0000153" ixz="-0.0000218" iyy="0.0023026" iyz="-0.0000265" izz="0.0019807"/>
    </inertial>
  </link>
  <link name="RF_SHANK">
    <inertial>
      <origin xyz="0.0587332 0.0108244 -0.0980642" rpy="0. 0. 0."/>
      <mass value="0.3473751"/>
      <inertia ixx="0.0068581" ixy="-0.0000322" ixz="0.0014287" iyy="0.0077043" iyz="0.0003162" izz="0.0010194"/>
    </inertial>
  </link>
  <link name="RF_THIGH">
    <inertial>
      <origin xyz="-0.003898 -0.0542266 -0.2145834" rpy="0. 0. 0."/>
      <mass value="1.6349765"/>
      <inertia ixx="0.0120368" ixy="-0.0000676" ixz="0.0002878" iyy="0.0120644" iyz="0.0014061" izz="0.0024942"/>
    </inertial>
  </link>
  <link name="RH_FOOT">
    <inertial>
      <origin xyz="0. 0. 0.02325" rpy="0. 0. 0."/>
      <mass value="0.05"/>
      <inertia ixx="0.001" ixy="-0.0000003" ixz="0.0000068" iyy="0.001" iyz="-0.0000068" izz="0.0000083"/>
    </inertial>
  </link>
  <link name="RH_HIP">
    <inertial>
      <origin xyz="-0.0645163 0.0037871 -0.0001522" rpy="0. 0. 0."/>
      <mass value="1.4246206"/>
      <inertia ixx="0.0024302" ixy="-0.0000153" ixz="0.0000218" iyy="0.0023026" iyz="-0.0000265" izz="0.0019807"/>
    </inertial>
  </link>
  <link name="RH_SHANK">
    <inertial>
      <origin xyz="-0.0587332 0.0108244 -0.0980642" rpy="0. 0. 0."/>
      <mass value="0.3473751"/>
      <inertia ixx="0.0068581" ixy="0.0000322" ixz="-0.0014287" iyy="0.0077043" iyz="0.0003162" izz="0.0010194"/>
    </inertial>
  </link>
  <link name="RH_THIGH">
    <inertial>
      <origin xyz="0.003898 -0.0542266 -0.2145834" rpy="0. 0. 0."/>
      <mass value="1.6349765"/>
      <inertia ixx="0.0120368" ixy="0.0000676" ixz="-0.0002878" iyy="0.0120644" iyz="0.0014061" izz="0.0024942"/>
    </inertial>
  </link>
  <link name="anymal"/>
</robot>
