<?xml version="1.0" encoding="UTF-8"?>
<robot name="anymal_d">
  <joint name="LF_HAA" type="revolute">
    <origin xyz="0.304 0.109 0. " rpy="0. 0. 0."/>
    <parent link="anymal"/>
    <child link="LF_HIP"/>
    <axis xyz="1. 0. 0."/>
    <limit lower="-0.7853984" upper="0.6108654" effort="80." velocity="20.0712864"/>
  </joint>
  <joint name="LF_HFE" type="revolute">
    <origin xyz="0.069 0.006 0. " rpy="-3.1415927 -0.0000001 1.5707964"/>
    <parent link="LF_HIP"/>
    <child link="LF_THIGH"/>
    <axis xyz="1. 0. 0."/>
    <limit lower="-9.424778" upper="9.424778" effort="80." velocity="20.0712864"/>
  </joint>
  <joint name="LF_KFE" type="revolute">
    <origin xyz="0.1805 0. 0.285 " rpy="3.1415927 -0.0000001 0. "/>
    <parent link="LF_THIGH"/>
    <child link="LF_SHANK"/>
    <axis xyz="1. 0. 0."/>
    <limit lower="-9.424778" upper="9.424778" effort="80." velocity="20.0712864"/>
  </joint>
  <joint name="LF_shank_fixed_LF_FOOT" type="fixed">
    <origin xyz="0.02225 -0.1 -0.3924599" rpy="0. 0. -1.5707961"/>
    <parent link="LF_SHANK"/>
    <child link="LF_FOOT"/>
  </joint>
  <joint name="LH_HAA" type="revolute">
    <origin xyz="-0.304 0.109 0. " rpy="-3.1415927 -0.0000001 -0.0000001"/>
    <parent link="anymal"/>
    <child link="LH_HIP"/>
    <axis xyz="1. 0. 0."/>
    <limit lower="-0.7853984" upper="0.6108654" effort="80." velocity="20.0712864"/>
  </joint>
  <joint name="LH_HFE" type="revolute">
    <origin xyz="-0.069 -0.006 -0. " rpy="0.0000001 0.0000001 -1.5707961"/>
    <parent link="LH_HIP"/>
    <child link="LH_THIGH"/>
    <axis xyz="1. 0. 0."/>
    <limit lower="-9.424778" upper="9.424778" effort="80." velocity="20.0712864"/>
  </joint>
  <joint name="LH_KFE" type="revolute">
    <origin xyz="0.1805 0. 0.285 " rpy="3.1415927 -0.0000001 0.0000001"/>
    <parent link="LH_THIGH"/>
    <child link="LH_SHANK"/>
    <axis xyz="1. 0. 0."/>
    <limit lower="-9.424778" upper="9.424778" effort="80." velocity="20.0712864"/>
  </joint>
  <joint name="LH_shank_fixed_LH_FOOT" type="fixed">
    <origin xyz="0.02225 0.1 -0.39246" rpy="0. 0. -1.5707961"/>
    <parent link="LH_SHANK"/>
    <child link="LH_FOOT"/>
  </joint>
  <joint name="RF_HAA" type="revolute">
    <origin xyz="0.304 -0.109 0. " rpy="0. 0. 0."/>
    <parent link="anymal"/>
    <child link="RF_HIP"/>
    <axis xyz="1. 0. 0."/>
    <limit lower="-0.6108654" upper="0.7853984" effort="80." velocity="20.0712864"/>
  </joint>
  <joint name="RF_HFE" type="revolute">
    <origin xyz="0.069 -0.006 0. " rpy="0. 0. 1.5707964"/>
    <parent link="RF_HIP"/>
    <child link="RF_THIGH"/>
    <axis xyz="1. 0. 0."/>
    <limit lower="-9.424778" upper="9.424778" effort="80." velocity="20.0712864"/>
  </joint>
  <joint name="RF_KFE" type="revolute">
    <origin xyz="-0.1805 -0. -0.2849999" rpy="3.1415927 -0.0000001 0. "/>
    <parent link="RF_THIGH"/>
    <child link="RF_SHANK"/>
    <axis xyz="1. 0. 0."/>
    <limit lower="-9.424778" upper="9.424778" effort="80." velocity="20.0712864"/>
  </joint>
  <joint name="RF_shank_fixed_RF_FOOT" type="fixed">
    <origin xyz="-0.0222501 0.1 0.3924599" rpy="3.1415925 0. 1.5707966"/>
    <parent link="RF_SHANK"/>
    <child link="RF_FOOT"/>
  </joint>
  <joint name="RH_HAA" type="revolute">
    <origin xyz="-0.304 -0.109 0. " rpy="-3.1415927 -0.0000001 -0.0000001"/>
    <parent link="anymal"/>
    <child link="RH_HIP"/>
    <axis xyz="1. 0. 0."/>
    <limit lower="-0.6108654" upper="0.7853984" effort="80." velocity="20.0712864"/>
  </joint>
  <joint name="RH_HFE" type="revolute">
    <origin xyz="-0.069 0.006 -0. " rpy="-3.1415925 0. -1.5707961"/>
    <parent link="RH_HIP"/>
    <child link="RH_THIGH"/>
    <axis xyz="1. 0. 0."/>
    <limit lower="-9.424778" upper="9.424778" effort="80." velocity="20.0712864"/>
  </joint>
  <joint name="RH_KFE" type="revolute">
    <origin xyz="-0.1805 0. -0.2849999" rpy="-3.1415927 -0.0000001 -0. "/>
    <parent link="RH_THIGH"/>
    <child link="RH_SHANK"/>
    <axis xyz="1. 0. 0."/>
    <limit lower="-9.424778" upper="9.424778" effort="80." velocity="20.0712864"/>
  </joint>
  <joint name="RH_shank_fixed_RH_FOOT" type="fixed">
    <origin xyz="-0.02225 -0.1 0.3924599" rpy="3.1415925 0. 1.5707966"/>
    <parent link="RH_SHANK"/>
    <child link="RH_FOOT"/>
  </joint>
  <link name="LF_FOOT">
    <inertial>
      <origin xyz="0. -0.01559 0.15004" rpy="0. 0. 0."/>
      <mass value="0.29644"/>
      <inertia ixx="0.0051426" ixy="0." ixz="0." iyy="0.0051316" iyz="0.0001632" izz="0.0001189"/>
    </inertial>
  </link>
  <link name="LF_HIP">
    <inertial>
      <origin xyz="0.035047 -0.0012268 0. " rpy="0. 0. 0."/>
      <mass value="0.36586"/>
      <inertia ixx="0.0002385" ixy="0.0000033" ixz="0." iyy="0.0005582" iyz="0." izz="0.0004433"/>
    </inertial>
  </link>
  <link name="LF_SHANK">
    <inertial>
      <origin xyz="0.0089321 -0.0218162 0.0004192" rpy="0. 0. 0."/>
      <mass value="0.49954"/>
      <inertia ixx="0.0016712" ixy="-0.0000213" ixz="0.0000017" iyy="0.0005505" iyz="-0.0000169" izz="0.0012741"/>
    </inertial>
  </link>
  <link name="LF_THIGH">
    <inertial>
      <origin xyz="-0.0905113 -0.000088 -0.140188 " rpy="0. 0. 0."/>
      <mass value="5.1321998"/>
      <inertia ixx="0.1048802" ixy="-0.000142" ixz="-0.0200594" iyy="0.1079587" iyz="0.000403" izz="0.0139329"/>
    </inertial>
  </link>
  <link name="LH_FOOT">
    <inertial>
      <origin xyz="0. -0.01559 0.15004" rpy="0. 0. 0."/>
      <mass value="0.29644"/>
      <inertia ixx="0.0051426" ixy="-0." ixz="-0." iyy="0.0051316" iyz="0.0001632" izz="0.0001189"/>
    </inertial>
  </link>
  <link name="LH_HIP">
    <inertial>
      <origin xyz="0.035047 0.0012268 0. " rpy="0. 0. 0."/>
      <mass value="0.36586"/>
      <inertia ixx="0.0002385" ixy="-0.0000033" ixz="0." iyy="0.0005582" iyz="-0." izz="0.0004433"/>
    </inertial>
  </link>
  <link name="LH_SHANK">
    <inertial>
      <origin xyz="0.0089321 0.0218162 0.0004192" rpy="0. 0. 0."/>
      <mass value="0.49954"/>
      <inertia ixx="0.0016712" ixy="0.0000213" ixz="0.0000017" iyy="0.0005505" iyz="0.0000169" izz="0.0012741"/>
    </inertial>
  </link>
  <link name="LH_THIGH">
    <inertial>
      <origin xyz="-0.0905113 0.000088 -0.140188 " rpy="0. 0. 0."/>
      <mass value="5.1321998"/>
      <inertia ixx="0.1048802" ixy="0.0002813" ixz="-0.0200594" iyy="0.1079587" iyz="-0.0002422" izz="0.0139329"/>
    </inertial>
  </link>
  <link name="RF_FOOT">
    <inertial>
      <origin xyz="0. 0.01559 0.15004" rpy="0. 0. 0."/>
      <mass value="0.29644"/>
      <inertia ixx="0.0051426" ixy="-0." ixz="0." iyy="0.0051316" iyz="-0.0001632" izz="0.0001189"/>
    </inertial>
  </link>
  <link name="RF_HIP">
    <inertial>
      <origin xyz="0.035047 0.0012268 0. " rpy="0. 0. 0."/>
      <mass value="0.36586"/>
      <inertia ixx="0.0002385" ixy="-0.0000033" ixz="0." iyy="0.0005582" iyz="-0." izz="0.0004433"/>
    </inertial>
  </link>
  <link name="RF_SHANK">
    <inertial>
      <origin xyz="0.0089321 0.0218162 0.0004192" rpy="0. 0. 0."/>
      <mass value="0.49954"/>
      <inertia ixx="0.0016712" ixy="0.0000213" ixz="0.0000017" iyy="0.0005505" iyz="0.0000169" izz="0.0012741"/>
    </inertial>
  </link>
  <link name="RF_THIGH">
    <inertial>
      <origin xyz="-0.0905113 0.000088 -0.140188 " rpy="0. 0. 0."/>
      <mass value="5.1321998"/>
      <inertia ixx="0.1048802" ixy="0.0002813" ixz="-0.0200594" iyy="0.1079587" iyz="-0.0002422" izz="0.0139329"/>
    </inertial>
  </link>
  <link name="RH_FOOT">
    <inertial>
      <origin xyz="0. 0.01559 0.15004" rpy="0. 0. 0."/>
      <mass value="0.29644"/>
      <inertia ixx="0.0051426" ixy="0." ixz="-0." iyy="0.0051316" iyz="-0.0001632" izz="0.0001189"/>
    </inertial>
  </link>
  <link name="RH_HIP">
    <inertial>
      <origin xyz="0.035047 -0.0012268 0. " rpy="0. 0. 0."/>
      <mass value="0.36586"/>
      <inertia ixx="0.0002385" ixy="0.0000033" ixz="0." iyy="0.0005582" iyz="0." izz="0.0004433"/>
    </inertial>
  </link>
  <link name="RH_SHANK">
    <inertial>
      <origin xyz="0.0089321 -0.0218162 0.0004192" rpy="0. 0. 0."/>
      <mass value="0.49954"/>
      <inertia ixx="0.0016712" ixy="-0.0000213" ixz="0.0000017" iyy="0.0005505" iyz="-0.0000169" izz="0.0012741"/>
    </inertial>
  </link>
  <link name="RH_THIGH">
    <inertial>
      <origin xyz="-0.0905113 -0.000088 -0.140188 " rpy="0. 0. 0."/>
      <mass value="5.1321998"/>
      <inertia ixx="0.1048802" ixy="-0.000142" ixz="-0.0200594" iyy="0.1079587" iyz="0.000403" izz="0.0139329"/>
    </inertial>
  </link>
  <link name="anymal"/>
</robot>
