<?xml version="1.0" encoding="UTF-8"?>
<robot name="go1">
  <joint name="FL_calf_joint" type="revolute">
    <origin xyz="-0. 0. -0.213" rpy="0. 0. 0."/>
    <parent link="FL_thigh"/>
    <child link="FL_calf"/>
    <axis xyz="1. 0. 0."/>
    <limit lower="-2.8179999" upper="-0.888" effort="35.5499992" velocity="20.0599989"/>
  </joint>
  <joint name="FL_foot_fixed" type="fixed">
    <origin xyz="0. 0. -0.213" rpy="0. 0. -1.5707964"/>
    <parent link="FL_calf"/>
    <child link="FL_foot"/>
  </joint>
  <joint name="FL_hip_joint" type="revolute">
    <origin xyz="0.1881 0.04675 0. " rpy="0. 0. 0."/>
    <parent link="go1"/>
    <child link="FL_hip"/>
    <axis xyz="1. 0. 0."/>
    <limit lower="-0.8629999" upper="0.8629999" effort="23.7000008" velocity="30.1000011"/>
  </joint>
  <joint name="FL_thigh_joint" type="revolute">
    <origin xyz="0. 0.08 0. " rpy="0. 0. 1.5707964"/>
    <parent link="FL_hip"/>
    <child link="FL_thigh"/>
    <axis xyz="1. 0. 0."/>
    <limit lower="-0.6859999" upper="4.5009995" effort="23.7000008" velocity="30.1000011"/>
  </joint>
  <joint name="FR_calf_joint" type="revolute">
    <origin xyz="0. 0. -0.213" rpy="0. 0. 0."/>
    <parent link="FR_thigh"/>
    <child link="FR_calf"/>
    <axis xyz="1. 0. 0."/>
    <limit lower="-2.8179999" upper="-0.888" effort="35.5499992" velocity="20.0599989"/>
  </joint>
  <joint name="FR_foot_fixed" type="fixed">
    <origin xyz="0. 0. -0.213" rpy="0. 0. -1.5707964"/>
    <parent link="FR_calf"/>
    <child link="FR_foot"/>
  </joint>
  <joint name="FR_hip_joint" type="revolute">
    <origin xyz="0.1881 -0.04675 0. " rpy="0. 0. 0."/>
    <parent link="go1"/>
    <child link="FR_hip"/>
    <axis xyz="1. 0. 0."/>
    <limit lower="-0.8629999" upper="0.8629999" effort="23.7000008" velocity="30.1000011"/>
  </joint>
  <joint name="FR_thigh_joint" type="revolute">
    <origin xyz="0. -0.08 0. " rpy="0. 0. 1.5707964"/>
    <parent link="FR_hip"/>
    <child link="FR_thigh"/>
    <axis xyz="1. 0. 0."/>
    <limit lower="-0.6859999" upper="4.5009995" effort="23.7000008" velocity="30.1000011"/>
  </joint>
  <joint name="RL_calf_joint" type="revolute">
    <origin xyz="-0. 0. -0.213" rpy="0. 0. 0."/>
    <parent link="RL_thigh"/>
    <child link="RL_calf"/>
    <axis xyz="1. 0. 0."/>
    <limit lower="-2.8179999" upper="-0.888" effort="35.5499992" velocity="20.0599989"/>
  </joint>
  <joint name="RL_foot_fixed" type="fixed">
    <origin xyz="0. 0. -0.213" rpy="0. 0. -1.5707964"/>
    <parent link="RL_calf"/>
    <child link="RL_foot"/>
  </joint>
  <joint name="RL_hip_joint" type="revolute">
    <origin xyz="-0.1881 0.04675 0. " rpy="0. 0. 0."/>
    <parent link="go1"/>
    <child link="RL_hip"/>
    <axis xyz="1. 0. 0."/>
    <limit lower="-0.8629999" upper="0.8629999" effort="23.7000008" velocity="30.1000011"/>
  </joint>
  <joint name="RL_thigh_joint" type="revolute">
    <origin xyz="0. 0.08 0. " rpy="0. 0. 1.5707964"/>
    <parent link="RL_hip"/>
    <child link="RL_thigh"/>
    <axis xyz="1. 0. 0."/>
    <limit lower="-0.6859999" upper="4.5009995" effort="23.7000008" velocity="30.1000011"/>
  </joint>
  <joint name="RR_calf_joint" type="revolute">
    <origin xyz="0. 0. -0.213" rpy="0. 0. 0."/>
    <parent link="RR_thigh"/>
    <child link="RR_calf"/>
    <axis xyz="1. 0. 0."/>
    <limit lower="-2.8179999" upper="-0.888" effort="35.5499992" velocity="20.0599989"/>
  </joint>
  <joint name="RR_foot_fixed" type="fixed">
    <origin xyz="0. 0. -0.213" rpy="0. 0. -1.5707964"/>
    <parent link="RR_calf"/>
    <child link="RR_foot"/>
  </joint>
  <joint name="RR_hip_joint" type="revolute">
    <origin xyz="-0.1881 -0.04675 0. " rpy="0. 0. 0."/>
    <parent link="go1"/>
    <child link="RR_hip"/>
    <axis xyz="1. 0. 0."/>
    <limit lower="-0.8629999" upper="0.8629999" effort="23.7000008" velocity="30.1000011"/>
  </joint>
  <joint name="RR_thigh_joint" type="revolute">
    <origin xyz="0. -0.08 0. " rpy="0. 0. 1.5707964"/>
    <parent link="RR_hip"/>
    <child link="RR_thigh"/>
    <axis xyz="1. 0. 0."/>
    <limit lower="-0.6859999" upper="4.5009995" effort="23.7000008" velocity="30.1000011"/>
  </joint>
  <link name="FL_calf">
    <inertial>
      <origin xyz="0.006197 0.001408 -0.116695" rpy="0. 0. 0."/>
      <mass value="0.135862"/>
      <inertia ixx="0.0010888" ixy="-0.0000003" ixz="0.0000071" iyy="0.0011004" iyz="0.0000021" izz="0.0000248"/>
    </inertial>
  </link>
  <link name="FL_foot">
    <inertial>
      <origin xyz="-inf -inf -inf" rpy="0. 0. 0."/>
      <mass value="0.06"/>
      <inertia ixx="0.0000096" ixy="0." ixz="0." iyy="0.0000096" iyz="0." izz="0.0000096"/>
    </inertial>
  </link>
  <link name="FL_hip">
    <inertial>
      <origin xyz="-0.0049166 -0.0076261 -0.0000886" rpy="0. 0. 0."/>
      <mass value="0.68"/>
      <inertia ixx="0.0003994" ixy="-0.0000146" ixz="0.0000012" iyy="0.0007334" iyz="0.0000016" izz="0.0004684"/>
    </inertial>
  </link>
  <link name="FL_thigh">
    <inertial>
      <origin xyz="-0.0030472 -0.019315 -0.0305004" rpy="0. 0. 0."/>
      <mass value="1.0090001"/>
      <inertia ixx="0.0045988" ixy="0.0000614" ixz="-0.0002275" iyy="0.0046892" iyz="0.0006108" izz="0.0008174"/>
    </inertial>
  </link>
  <link name="FR_calf">
    <inertial>
      <origin xyz="0.006197 0.001408 -0.116695" rpy="0. 0. 0."/>
      <mass value="0.135862"/>
      <inertia ixx="0.0010888" ixy="-0.0000003" ixz="0.0000071" iyy="0.0011004" iyz="0.0000021" izz="0.0000248"/>
    </inertial>
  </link>
  <link name="FR_foot">
    <inertial>
      <origin xyz="-inf -inf -inf" rpy="0. 0. 0."/>
      <mass value="0.06"/>
      <inertia ixx="0.0000096" ixy="0." ixz="0." iyy="0.0000096" iyz="0." izz="0.0000096"/>
    </inertial>
  </link>
  <link name="FR_hip">
    <inertial>
      <origin xyz="-0.0049166 0.0076261 -0.0000886" rpy="0. 0. 0."/>
      <mass value="0.68"/>
      <inertia ixx="0.0003994" ixy="0.0000146" ixz="0.0000012" iyy="0.0007334" iyz="-0.0000016" izz="0.0004684"/>
    </inertial>
  </link>
  <link name="FR_thigh">
    <inertial>
      <origin xyz="-0.0030472 0.019315 -0.0305004" rpy="0. 0. 0."/>
      <mass value="1.0090001"/>
      <inertia ixx="0.0045988" ixy="-0.0000614" ixz="-0.0002275" iyy="0.0046892" iyz="-0.0006108" izz="0.0008174"/>
    </inertial>
  </link>
  <link name="RL_calf">
    <inertial>
      <origin xyz="0.006197 0.001408 -0.116695" rpy="0. 0. 0."/>
      <mass value="0.135862"/>
      <inertia ixx="0.0010888" ixy="-0.0000003" ixz="0.0000071" iyy="0.0011004" iyz="0.0000021" izz="0.0000248"/>
    </inertial>
  </link>
  <link name="RL_foot">
    <inertial>
      <origin xyz="-inf -inf -inf" rpy="0. 0. 0."/>
      <mass value="0.06"/>
      <inertia ixx="0.0000096" ixy="0." ixz="0." iyy="0.0000096" iyz="0." izz="0.0000096"/>
    </inertial>
  </link>
  <link name="RL_hip">
    <inertial>
      <origin xyz="0.0049166 -0.0076261 -0.0000886" rpy="0. 0. 0."/>
      <mass value="0.68"/>
      <inertia ixx="0.0003994" ixy="0.0000146" ixz="-0.0000012" iyy="0.0007334" iyz="0.0000016" izz="0.0004684"/>
    </inertial>
  </link>
  <link name="RL_thigh">
    <inertial>
      <origin xyz="-0.0030472 -0.019315 -0.0305004" rpy="0. 0. 0."/>
      <mass value="1.0090001"/>
      <inertia ixx="0.0045988" ixy="0.0000614" ixz="-0.0002275" iyy="0.0046892" iyz="0.0006108" izz="0.0008174"/>
    </inertial>
  </link>
  <link name="RR_calf">
    <inertial>
      <origin xyz="0.006197 0.001408 -0.116695" rpy="0. 0. 0."/>
      <mass value="0.135862"/>
      <inertia ixx="0.0010888" ixy="-0.0000003" ixz="0.0000071" iyy="0.0011004" iyz="0.0000021" izz="0.0000248"/>
    </inertial>
  </link>
  <link name="RR_foot">
    <inertial>
      <origin xyz="-inf -inf -inf" rpy="0. 0. 0."/>
      <mass value="0.06"/>
      <inertia ixx="0.0000096" ixy="0." ixz="0." iyy="0.0000096" iyz="0." izz="0.0000096"/>
    </inertial>
  </link>
  <link name="RR_hip">
    <inertial>
      <origin xyz="0.0049166 0.0076261 -0.0000886" rpy="0. 0. 0."/>
      <mass value="0.68"/>
      <inertia ixx="0.0003994" ixy="-0.0000146" ixz="-0.0000012" iyy="0.0007334" iyz="-0.0000016" izz="0.0004684"/>
    </inertial>
  </link>
  <link name="RR_thigh">
    <inertial>
      <origin xyz="-0.0030472 0.019315 -0.0305004" rpy="0. 0. 0."/>
      <mass value="1.0090001"/>
      <inertia ixx="0.0045988" ixy="-0.0000614" ixz="-0.0002275" iyy="0.0046892" iyz="-0.0006108" izz="0.0008174"/>
    </inertial>
  </link>
  <link name="go1"/>
</robot>
