<?xml version="1.0" encoding="UTF-8"?>
<robot name="go2">
  <joint name="FL_calf_joint" type="revolute">
    <origin xyz="0. 0. -0.213" rpy="0. 0. 0."/>
    <parent link="FL_thigh"/>
    <child link="FL_calf"/>
    <axis xyz="1. 0. 0."/>
    <limit lower="-2.7227001" upper="-0.8377599" effort="45.4300003" velocity="15.6999994"/>
  </joint>
  <joint name="FL_foot_joint" type="fixed">
    <origin xyz="0. 0. -0.213" rpy="1.5707964 1.5707964 0. "/>
    <parent link="FL_calf"/>
    <child link="FL_foot"/>
  </joint>
  <joint name="FL_hip_joint" type="revolute">
    <origin xyz="0.1934 0.0465 0. " rpy="0. 0. 0."/>
    <parent link="go2_description"/>
    <child link="FL_hip"/>
    <axis xyz="1. 0. 0."/>
    <limit lower="-1.0471999" upper="1.0471999" effort="23.7000008" velocity="30.1000011"/>
  </joint>
  <joint name="FL_thigh_joint" type="revolute">
    <origin xyz="0. 0.0955 0. " rpy="0. 0. 1.5707964"/>
    <parent link="FL_hip"/>
    <child link="FL_thigh"/>
    <axis xyz="1. 0. 0."/>
    <limit lower="-1.5707999" upper="3.4906998" effort="23.7000008" velocity="30.1000011"/>
  </joint>
  <joint name="FR_calf_joint" type="revolute">
    <origin xyz="-0. 0. -0.213" rpy="0. 0. 0."/>
    <parent link="FR_thigh"/>
    <child link="FR_calf"/>
    <axis xyz="1. 0. 0."/>
    <limit lower="-2.7227001" upper="-0.8377599" effort="45.4300003" velocity="15.6999994"/>
  </joint>
  <joint name="FR_foot_joint" type="fixed">
    <origin xyz="0. 0. -0.213" rpy="1.5707964 1.5707964 0. "/>
    <parent link="FR_calf"/>
    <child link="FR_foot"/>
  </joint>
  <joint name="FR_hip_joint" type="revolute">
    <origin xyz="0.1934 -0.0465 0. " rpy="0. 0. 0."/>
    <parent link="go2_description"/>
    <child link="FR_hip"/>
    <axis xyz="1. 0. 0."/>
    <limit lower="-1.0471999" upper="1.0471999" effort="23.7000008" velocity="30.1000011"/>
  </joint>
  <joint name="FR_thigh_joint" type="revolute">
    <origin xyz="0. -0.0955 0. " rpy="0. 0. 1.5707964"/>
    <parent link="FR_hip"/>
    <child link="FR_thigh"/>
    <axis xyz="1. 0. 0."/>
    <limit lower="-1.5707999" upper="3.4906998" effort="23.7000008" velocity="30.1000011"/>
  </joint>
  <joint name="Head_lower_joint" type="fixed">
    <origin xyz="0.07 0. 0.008" rpy="0. 0. 0."/>
    <parent link="Head_upper"/>
    <child link="Head_lower"/>
  </joint>
  <joint name="Head_upper_joint" type="fixed">
    <origin xyz="0.285 0. 0.01 " rpy="0. 1.5707963 0. "/>
    <parent link="go2_description"/>
    <child link="Head_upper"/>
  </joint>
  <joint name="RL_calf_joint" type="revolute">
    <origin xyz="0. 0. -0.213" rpy="0. 0. 0."/>
    <parent link="RL_thigh"/>
    <child link="RL_calf"/>
    <axis xyz="1. 0. 0."/>
    <limit lower="-2.7227001" upper="-0.8377599" effort="45.4300003" velocity="15.6999994"/>
  </joint>
  <joint name="RL_foot_joint" type="fixed">
    <origin xyz="0. 0. -0.213" rpy="1.5707964 1.5707964 0. "/>
    <parent link="RL_calf"/>
    <child link="RL_foot"/>
  </joint>
  <joint name="RL_hip_joint" type="revolute">
    <origin xyz="-0.1934 0.0465 0. " rpy="0. 0. 0."/>
    <parent link="go2_description"/>
    <child link="RL_hip"/>
    <axis xyz="1. 0. 0."/>
    <limit lower="-1.0471999" upper="1.0471999" effort="23.7000008" velocity="30.1000011"/>
  </joint>
  <joint name="RL_thigh_joint" type="revolute">
    <origin xyz="0. 0.0955 0. " rpy="0. 0. 1.5707964"/>
    <parent link="RL_hip"/>
    <child link="RL_thigh"/>
    <axis xyz="1. 0. 0."/>
    <limit lower="-0.5235999" upper="4.5378997" effort="23.7000008" velocity="30.1000011"/>
  </joint>
  <joint name="RR_calf_joint" type="revolute">
    <origin xyz="-0. 0. -0.213" rpy="0. 0. 0."/>
    <parent link="RR_thigh"/>
    <child link="RR_calf"/>
    <axis xyz="1. 0. 0."/>
    <limit lower="-2.7227001" upper="-0.8377599" effort="45.4300003" velocity="15.6999994"/>
  </joint>
  <joint name="RR_foot_joint" type="fixed">
    <origin xyz="0. 0. -0.213" rpy="1.5707964 1.5707964 0. "/>
    <parent link="RR_calf"/>
    <child link="RR_foot"/>
  </joint>
  <joint name="RR_hip_joint" type="revolute">
    <origin xyz="-0.1934 -0.0465 0. " rpy="0. 0. 0."/>
    <parent link="go2_description"/>
    <child link="RR_hip"/>
    <axis xyz="1. 0. 0."/>
    <limit lower="-1.0471999" upper="1.0471999" effort="23.7000008" velocity="30.1000011"/>
  </joint>
  <joint name="RR_thigh_joint" type="revolute">
    <origin xyz="0. -0.0955 0. " rpy="0. 0. 1.5707964"/>
    <parent link="RR_hip"/>
    <child link="RR_thigh"/>
    <axis xyz="1. 0. 0."/>
    <limit lower="-0.5235999" upper="4.5378997" effort="23.7000008" velocity="30.1000011"/>
  </joint>
  <link name="FL_calf">
    <inertial>
      <origin xyz="0.00548 -0.000975 -0.115 " rpy="0. 0. 0."/>
      <mass value="0.154"/>
      <inertia ixx="0.00108" ixy="0.0000003" ixz="0.0000172" iyy="0.0011" iyz="0.0000083" izz="0.0000329"/>
    </inertial>
  </link>
  <link name="FL_foot">
    <inertial>
      <origin xyz="0. 0. 0." rpy="0. 0. 0."/>
      <mass value="0.04"/>
      <inertia ixx="0.0000096" ixy="0." ixz="0." iyy="0.0000096" iyz="0." izz="0.0000096"/>
    </inertial>
  </link>
  <link name="FL_hip">
    <inertial>
      <origin xyz="-0.0054 0.00194 -0.000105" rpy="0. 0. 0."/>
      <mass value="0.678"/>
      <inertia ixx="0.00048" ixy="-0.000003" ixz="0.0000011" iyy="0.000884" iyz="-0.0000014" izz="0.000596"/>
    </inertial>
  </link>
  <link name="FL_thigh">
    <inertial>
      <origin xyz="-0.00374 -0.0223 -0.0327 " rpy="0. 0. 0."/>
      <mass value="1.152"/>
      <inertia ixx="0.00584" ixy="0.0000872" ixz="-0.000289" iyy="0.0058" iyz="0.000808" izz="0.00103"/>
    </inertial>
  </link>
  <link name="FR_calf">
    <inertial>
      <origin xyz="0.00548 0.000975 -0.115 " rpy="0. 0. 0."/>
      <mass value="0.154"/>
      <inertia ixx="0.00108" ixy="-0.0000003" ixz="0.0000172" iyy="0.0011" iyz="-0.0000083" izz="0.0000329"/>
    </inertial>
  </link>
  <link name="FR_foot">
    <inertial>
      <origin xyz="0. 0. 0." rpy="0. 0. 0."/>
      <mass value="0.04"/>
      <inertia ixx="0.0000096" ixy="0." ixz="0." iyy="0.0000096" iyz="0." izz="0.0000096"/>
    </inertial>
  </link>
  <link name="FR_hip">
    <inertial>
      <origin xyz="-0.0054 -0.00194 -0.000105" rpy="0. 0. 0."/>
      <mass value="0.678"/>
      <inertia ixx="0.00048" ixy="0.000003" ixz="0.0000011" iyy="0.000884" iyz="0.0000014" izz="0.000596"/>
    </inertial>
  </link>
  <link name="FR_thigh">
    <inertial>
      <origin xyz="-0.00374 0.0223 -0.0327 " rpy="0. 0. 0."/>
      <mass value="1.152"/>
      <inertia ixx="0.00584" ixy="-0.0000872" ixz="-0.000289" iyy="0.0058" iyz="-0.000808" izz="0.00103"/>
    </inertial>
  </link>
  <link name="Head_lower">
    <inertial>
      <origin xyz="0. 0. 0." rpy="0. 0. 0."/>
      <mass value="0.001"/>
      <inertia ixx="0.0000096" ixy="0." ixz="0." iyy="0.0000096" iyz="0." izz="0.0000096"/>
    </inertial>
  </link>
  <link name="Head_upper">
    <inertial>
      <origin xyz="0. 0. 0." rpy="0. 0. 0."/>
      <mass value="0.001"/>
      <inertia ixx="0.0000096" ixy="0." ixz="0." iyy="0.0000096" iyz="0." izz="0.0000096"/>
    </inertial>
  </link>
  <link name="RL_calf">
    <inertial>
      <origin xyz="0.00548 -0.000975 -0.115 " rpy="0. 0. 0."/>
      <mass value="0.154"/>
      <inertia ixx="0.00108" ixy="0.0000003" ixz="0.0000172" iyy="0.0011" iyz="0.0000083" izz="0.0000329"/>
    </inertial>
  </link>
  <link name="RL_foot">
    <inertial>
      <origin xyz="0. 0. 0." rpy="0. 0. 0."/>
      <mass value="0.04"/>
      <inertia ixx="0.0000096" ixy="0." ixz="0." iyy="0.0000096" iyz="0." izz="0.0000096"/>
    </inertial>
  </link>
  <link name="RL_hip">
    <inertial>
      <origin xyz="0.0054 0.00194 -0.000105" rpy="0. 0. 0."/>
      <mass value="0.678"/>
      <inertia ixx="0.00048" ixy="0.000003" ixz="-0.0000011" iyy="0.000884" iyz="-0.0000014" izz="0.000596"/>
    </inertial>
  </link>
  <link name="RL_thigh">
    <inertial>
      <origin xyz="-0.00374 -0.0223 -0.0327 " rpy="0. 0. 0."/>
      <mass value="1.152"/>
      <inertia ixx="0.00584" ixy="0.0000872" ixz="-0.000289" iyy="0.0058" iyz="0.000808" izz="0.00103"/>
    </inertial>
  </link>
  <link name="RR_calf">
    <inertial>
      <origin xyz="0.00548 0.000975 -0.115 " rpy="0. 0. 0."/>
      <mass value="0.154"/>
      <inertia ixx="0.00108" ixy="-0.0000003" ixz="0.0000172" iyy="0.0011" iyz="-0.0000083" izz="0.0000329"/>
    </inertial>
  </link>
  <link name="RR_foot">
    <inertial>
      <origin xyz="0. 0. 0." rpy="0. 0. 0."/>
      <mass value="0.04"/>
      <inertia ixx="0.0000096" ixy="0." ixz="0." iyy="0.0000096" iyz="0." izz="0.0000096"/>
    </inertial>
  </link>
  <link name="RR_hip">
    <inertial>
      <origin xyz="0.0054 -0.00194 -0.000105" rpy="0. 0. 0."/>
      <mass value="0.678"/>
      <inertia ixx="0.00048" ixy="-0.000003" ixz="-0.0000011" iyy="0.000884" iyz="0.0000014" izz="0.000596"/>
    </inertial>
  </link>
  <link name="RR_thigh">
    <inertial>
      <origin xyz="-0.00374 0.0223 -0.0327 " rpy="0. 0. 0."/>
      <mass value="1.152"/>
      <inertia ixx="0.00584" ixy="-0.0000872" ixz="-0.000289" iyy="0.0058" iyz="-0.000808" izz="0.00103"/>
    </inertial>
  </link>
  <link name="go2_description"/>
</robot>
